Workbook

Sheet Consolidated Games
A1: MAJOR GAME | B1: YEAR | C1: SPORT GROUP | D1: SPORT | E1: DISCIPLINE | F1: EVENT_GENDER | G1: EVENT | H1: ORIGNAL_SPORT | I1: ORIGINAL_EVENT | J1: ATHLETE_NAME | K1: COUNTRY_CODE | L1: POSITION | M1: MEDAL_COLOUR | N1: MEDAL_POSITION | O1: COUNT | P1: IS DEMO SPORT | Q1: SGP PARTICIPATED? | R1: REMARKS | S1: CHANGE_LOG_# | T1: ROW_ID
A2: SEA GAMES | B2: 1967 | C2: CYCLING | D2: CYCLING | E2: TRACK | F2: MEN | H2: Cycling | I2: SMALL BORE RIFLE PRONE-_x000D_ INDIVIDUAL | K2: SGP | L2: 2 | M2: SILVER | N2: 2 | O2: 1 | P2: NO | Q2: YES | S2: {=IFERROR(_xlfn.TEXTJOIN(", ",TRUE,IF(ChangeLog[ROW_ID]=$T2,ChangeLog[Change'#],"")),"")} -> 385 | T2: 890
A3: SEA GAMES | B3: 1991 | C3: ATHLETICS | D3: ATHLETICS | E3: COMBINED | F3: WOMEN | G3: HEPTATHLON | H3: Athletics | I3: HEPATHLON | J3: YU LONG NYU | K3: SGP | L3: 3 | M3: BRONZE | N3: 3 | O3: 1 | P3: NO | Q3: YES | R3: 4, 831 POINTS | S3: {=IFERROR(_xlfn.TEXTJOIN(", ",TRUE,IF(ChangeLog[ROW_ID]=$T3,ChangeLog[Change'#],"")),"")} | T3: 1998
A4: SEA GAMES | B4: 1971 | C4: AQUATICS | D4: DIVING | E4: DIVING | F4: WOMEN | G4: 3M SPRINGBOARD | H4: Swimming | I4: SPRINGBOARD DIVING | J4: NORA TAY | K4: SGP | L4: 1 | M4: GOLD | N4: 1 | O4: 1 | P4: NO | Q4: YES | R4: 271.77 POINTS | S4: {=IFERROR(_xlfn.TEXTJOIN(", ",TRUE,IF(ChangeLog[ROW_ID]=$T4,ChangeLog[Change'#],"")),"")} -> 27 | T4: 1009
A5: SEA GAMES | B5: 1971 | C5: AQUATICS | D5: WATER POLO | E5: WATER POLO | G5: TEAM | H5: Waterpolo | J5: SINGAPORE | K5: SGP | L5: 1 | M5: GOLD | N5: 1 | O5: 1 | P5: NO | Q5: YES | S5: {=IFERROR(_xlfn.TEXTJOIN(", ",TRUE,IF(ChangeLog[ROW_ID]=$T5,ChangeLog[Change'#],"")),"")} -> 28 | T5: 1010
A6: SEA GAMES | B6: 1971 | C6: AQUATICS | D6: SWIMMING | E6: SWIMMING | G6: 200M BREASTSTROKE | H6: Swimming | I6: 200 METRES BREASTSTROKE | J6: ALAN R LELAH | K6: SGP | L6: 3 | M6: BRONZE | N6: 3 | O6: 1 | P6: NO | Q6: YES | R6: 2: 44.21 SEC | S6: {=IFERROR(_xlfn.TEXTJOIN(", ",TRUE,IF(ChangeLog[ROW_ID]=$T6,ChangeLog[Change'#],"")),"")} | T6: 1011
A7: SEA GAMES | B7: 1971 | C7: AQUATICS | D7: SWIMMING | E7: SWIMMING | F7: WOMEN | G7: 100M FREESTYLE | H7: Swimming | I7: 100 METRES FREESTYLE | J7: ELAINE SNG | K7: SGP | L7: 3 | M7: BRONZE | N7: 3 | O7: 1 | P7: NO | Q7: YES | R7: 1: 06.38 SEC | S7: {=IFERROR(_xlfn.TEXTJOIN(", ",TRUE,IF(ChangeLog[ROW_ID]=$T7,ChangeLog[Change'#],"")),"")} | T7: 1012
A8: SEA GAMES | B8: 1975 | C8: CYCLING | D8: CYCLING | E8: TRACK | G8: 170KM MASSED START TEAM | H8: Cycling | I8: 170M MASSED START TEAM | J8: SINGAPORE | K8: SGP | L8: 2 | M8: SILVER | N8: 2 | O8: 1 | P8: NO | Q8: YES | R8: 25569.61 | S8: {=IFERROR(_xlfn.TEXTJOIN(", ",TRUE,IF(ChangeLog[ROW_ID]=$T8,ChangeLog[Change'#],"")),"")} -> 394 | T8: 1330
A9: SEA GAMES | B9: 1991 | C9: BADMINTON | D9: BADMINTON | E9: BADMINTON | F9: MEN | G9: TEAM | H9: Badminton | I9: MEN'S TEAM | J9: SINGAPORE | K9: SGP | L9: 3 | M9: BRONZE | N9: 3 | O9: 1 | P9: NO | Q9: YES | S9: {=IFERROR(_xlfn.TEXTJOIN(", ",TRUE,IF(ChangeLog[ROW_ID]=$T9,ChangeLog[Change'#],"")),"")} | T9: 1999
A10: SEA GAMES | B10: 1991 | C10: BODYBUILDING | D10: BODYBUILDING | E10: BODYBUILDING | F10: MEN | G10: 65KG | H10: BODYBUILDING | I10: BANTAMWEIGHT | J10: IBRAHIM SIHAT | K10: SGP | L10: 1 | M10: GOLD | N10: 1 | O10: 1 | P10: NO | Q10: YES | S10: {=IFERROR(_xlfn.TEXTJOIN(", ",TRUE,IF(ChangeLog[ROW_ID]=$T10,ChangeLog[Change'#],"")),"")} -> 95 | T10: 2002
A11: ASIAN GAMES | B11: 1951 | C11: ATHLETICS | D11: ATHLETICS | E11: TRACK | F11: WOMEN | G11: 200M | H11: ATHLETICS | I11: WOMEN'S 200M (27.2) | J11: LORENZA DOWDESWELL | K11: SGP | M11: SILVER | N11: 2 | O11: 1 | P11: NO | Q11: YES | R11: 27.2 | S11: {=IFERROR(_xlfn.TEXTJOIN(", ",TRUE,IF(ChangeLog[ROW_ID]=$T11,ChangeLog[Change'#],"")),"")} | T11: 9
A12: ASIAN GAMES | B12: 1951 | C12: AQUATICS | D12: SWIMMING | E12: SWIMMING | F12: MEN | G12: 100M FREESTYLE | H12: SWIMMING | I12: 100M FREESTYLE | J12: WIEBE WOLTERS | K12: SGP | M12: SILVER | N12: 2 | O12: 1 | P12: NO | Q12: YES | S12: {=IFERROR(_xlfn.TEXTJOIN(", ",TRUE,IF(ChangeLog[ROW_ID]=$T12,ChangeLog[Change'#],"")),"")} | T12: 1
A13: ASIAN GAMES | B13: 1951 | C13: AQUATICS | D13: SWIMMING | E13: SWIMMING | F13: MEN | G13: 3X100M MEDLEY RELAY | H13: SWIMMING | I13: 3X100M MEDLEY RELAY | J13: LIONEL CHEE TAN HWEE HOCK NEO CHWEE KOK | K13: SGP | M13: SILVER | N13: 2 | O13: 1 | P13: NO | Q13: YES | S13: {=IFERROR(_xlfn.TEXTJOIN(", ",TRUE,IF(ChangeLog[ROW_ID]=$T13,ChangeLog[Change'#],"")),"")} | T13: 2
A14: ASIAN GAMES | B14: 1951 | C14: AQUATICS | D14: WATER POLO | E14: WATER POLO | F14: MEN | G14: TEAM | H14: WATERPOLO | I14: TEAM | J14: KEE SOON BEE TAN HWEE HOCK LIONEL CHEE HO KIAN BIN KEITH MITCHELL WIEBE WOLTERS TAN WEE ENG BARRY MITCHELL | K14: SGP | M14: SILVER | N14: 2 | O14: 1 | P14: NO | Q14: YES | S14: {=IFERROR(_xlfn.TEXTJOIN(", ",TRUE,IF(ChangeLog[ROW_ID]=$T14,ChangeLog[Change'#],"")),"")} | T14: 3
A15: ASIAN GAMES | B15: 1951 | C15: AQUATICS | D15: SWIMMING | E15: SWIMMING | F15: MEN | G15: 400M FREESTYLE | H15: SWIMMING | I15: 400M FREESTYLE (5:13.8) | J15: NEO CHWEE KOK | K15: SGP | M15: GOLD | N15: 1 | O15: 1 | P15: NO | Q15: YES | R15: 0.0036319444 | S15: {=IFERROR(_xlfn.TEXTJOIN(", ",TRUE,IF(ChangeLog[ROW_ID]=$T15,ChangeLog[Change'#],"")),"")} | T15: 4
A16: ASIAN GAMES | B16: 1951 | C16: AQUATICS | D16: SWIMMING | E16: SWIMMING | F16: MEN | G16: 4X100M FREESTYLE RELAY | H16: SWIMMING | I16: 4 X 100M FREESTYLE (4:19.8) | J16: NEO CHWEE KOK LIONEL CHEE WIEBE WOLTERS BARRY MITCHELL | K16: SGP | M16: GOLD | N16: 1 | O16: 1 | P16: NO | Q16: YES | R16: 0.0030069444 | S16: {=IFERROR(_xlfn.TEXTJOIN(", ",TRUE,IF(ChangeLog[ROW_ID]=$T16,ChangeLog[Change'#],"")),"")} | T16: 5
A17: ASIAN GAMES | B17: 1951 | C17: AQUATICS | D17: SWIMMING | E17: SWIMMING | F17: MEN | G17: 1500M FREESTYLE | H17: SWIMMING | I17: 1500M FREESTYLE | J17: NEO CHWEE KOK | K17: SGP | M17: GOLD | N17: 1 | O17: 1 | P17: NO | Q17: YES | S17: {=IFERROR(_xlfn.TEXTJOIN(", ",TRUE,IF(ChangeLog[ROW_ID]=$T17,ChangeLog[Change'#],"")),"")} | T17: 6
A18: ASIAN GAMES | B18: 1951 | C18: AQUATICS | D18: SWIMMING | E18: SWIMMING | F18: MEN | G18: 800M FREESTYLE | H18: SWIMMING | I18: 800M FREESTYLE (11:02.2) | J18: NEO CHWEE KOK | K18: SGP | M18: GOLD | N18: 1 | O18: 1 | P18: NO | Q18: YES | R18: 0.0076643519 | S18: {=IFERROR(_xlfn.TEXTJOIN(", ",TRUE,IF(ChangeLog[ROW_ID]=$T18,ChangeLog[Change'#],"")),"")} | T18: 7
A19: ASIAN GAMES | B19: 1951 | C19: ATHLETICS | D19: ATHLETICS | E19: TRACK | F19: WOMEN | G19: 80M HURDLES | H19: ATHLETICS | I19: WOMEN'S 80M HURDLES (13.5) | J19: LORENZA DOWDESWELL | K19: SGP | M19: SILVER | N19: 2 | O19: 1 | P19: NO | Q19: YES | R19: 13.5 | S19: {=IFERROR(_xlfn.TEXTJOIN(", ",TRUE,IF(ChangeLog[ROW_ID]=$T19,ChangeLog[Change'#],"")),"")} | T19: 8
A20: ASIAN GAMES | B20: 1951 | C20: ATHLETICS | D20: ATHLETICS | E20: TRACK | F20: MEN | G20: 110M HURDLES | H20: ATHLETICS | I20: 110M HURDLES (15.2) | J20: NG LIANG CHIANG | K20: SGP | M20: GOLD | N20: 1 | O20: 1 | P20: NO | Q20: YES | R20: 15.2 | S20: {=IFERROR(_xlfn.TEXTJOIN(", ",TRUE,IF(ChangeLog[ROW_ID]=$T20,ChangeLog[Change'#],"")),"")} | T20: 10
A21: ASIAN GAMES | B21: 1951 | C21: ATHLETICS | D21: ATHLETICS | E21: TRACK | F21: MEN | G21: 110M HURDLES | H21: ATHLETICS | I21: 110M HURDLES (15.7) | J21: LLOYD VALBERG | K21: SGP | M21: BRONZE | N21: 3 | O21: 1 | P21: NO | Q21: YES | R21: 15.7 | S21: {=IFERROR(_xlfn.TEXTJOIN(", ",TRUE,IF(ChangeLog[ROW_ID]=$T21,ChangeLog[Change'#],"")),"")} | T21: 11
A22: ASIAN GAMES | B22: 1951 | C22: ATHLETICS | D22: ATHLETICS | E22: TRACK | F22: MEN | G22: 400M HURDLES | H22: ATHLETICS | I22: 400M HURDLES (57.6) | J22: NG LIANG CHIANG | K22: SGP | M22: BRONZE | N22: 3 | O22: 1 | P22: NO | Q22: YES | R22: 57.6 | S22: {=IFERROR(_xlfn.TEXTJOIN(", ",TRUE,IF(ChangeLog[ROW_ID]=$T22,ChangeLog[Change'#],"")),"")} | T22: 12
A23: ASIAN GAMES | B23: 1951 | C23: WEIGHTLIFTING | D23: WEIGHTLIFTING | E23: WEIGHTLIFTING | F23: MEN | G23: 67.5KG | H23: WEIGHTLIFTING | I23: MEN 67.5KG | J23: PETER HO FOOM ONN | K23: SGP | M23: SILVER | N23: 2 | O23: 1 | P23: NO | Q23: YES | S23: {=IFERROR(_xlfn.TEXTJOIN(", ",TRUE,IF(ChangeLog[ROW_ID]=$T23,ChangeLog[Change'#],"")),"")} | T23: 13
A24: ASIAN GAMES | B24: 1951 | C24: WEIGHTLIFTING | D24: WEIGHTLIFTING | E24: WEIGHTLIFTING | F24: MEN | G24: LIGHT-HEAVYWEIGHT | H24: WEIGHTLIFTING | I24: MEN 82.5KG | J24: KOK CHEONG CHEONG | K24: SGP | M24: SILVER | N24: 2 | O24: 1 | P24: NO | Q24: YES | S24: {=IFERROR(_xlfn.TEXTJOIN(", ",TRUE,IF(ChangeLog[ROW_ID]=$T24,ChangeLog[Change'#],"")),"")} | T24: 14
A25: ASIAN GAMES | B25: 1954 | C25: AQUATICS | D25: SWIMMING | E25: SWIMMING | F25: MEN | G25: 4X200M FREESTYLE RELAY | H25: SWIMMING | I25: 4 X 200M FREESTYLE (9:27.0) | J25: NEO CHWEE KOK LIONEL CHEE ONG CHOON LIM TAN TEOW CHOON WIEBE WOLTERS | K25: SGP | M25: SILVER | N25: 2 | O25: 1 | P25: NO | Q25: YES | R25: 0.0065625 | S25: {=IFERROR(_xlfn.TEXTJOIN(", ",TRUE,IF(ChangeLog[ROW_ID]=$T25,ChangeLog[Change'#],"")),"")} | T25: 15
A26: ASIAN GAMES | B26: 1954 | C26: AQUATICS | D26: WATER POLO | E26: WATER POLO | F26: MEN | G26: TEAM | H26: WATERPOLO | I26: TEAM | J26: KEE SOON BEE TAN HWEE HOCK TAN ENG BOCK HO KIAN BIN GAN ENG TECK OH CHWEE HOCK WIEBE WOLTERS KEITH MITCHELL | K26: SGP | M26: GOLD | N26: 1 | O26: 1 | P26: NO | Q26: YES | S26: {=IFERROR(_xlfn.TEXTJOIN(", ",TRUE,IF(ChangeLog[ROW_ID]=$T26,ChangeLog[Change'#],"")),"")} | T26: 16
A27: ASIAN GAMES | B27: 1954 | C27: AQUATICS | D27: SWIMMING | E27: SWIMMING | F27: MEN | G27: 100M FREESTYLE | H27: SWIMMING | I27: 100M FREESTYLE (58.2) | J27: NEO CHWEE KOK | K27: SGP | M27: BRONZE | N27: 3 | O27: 1 | P27: NO | Q27: YES | R27: 58.2 | S27: {=IFERROR(_xlfn.TEXTJOIN(", ",TRUE,IF(ChangeLog[ROW_ID]=$T27,ChangeLog[Change'#],"")),"")} | T27: 17
A28: ASIAN GAMES | B28: 1954 | C28: ATHLETICS | D28: ATHLETICS | E28: TRACK | G28: 400M HURDLES | H28: ATHLETICS | I28: 400M HURDLES (54.8) | J28: CHAN ONN LENG | K28: SGP | M28: SILVER | N28: 2 | O28: 1 | P28: NO | Q28: YES | R28: 54.8 | S28: {=IFERROR(_xlfn.TEXTJOIN(", ",TRUE,IF(ChangeLog[ROW_ID]=$T28,ChangeLog[Change'#],"")),"")} | T28: 18
A29: ASIAN GAMES | B29: 1954 | C29: ATHLETICS | D29: ATHLETICS | E29: TRACK | G29: 80M HURDLES | H29: ATHLETICS | I29: 80M HURDLES (12.1) | J29: TANG PEI WAH | K29: SGP | M29: BRONZE | N29: 3 | O29: 1 | P29: NO | Q29: YES | R29: 12.1 | S29: {=IFERROR(_xlfn.TEXTJOIN(", ",TRUE,IF(ChangeLog[ROW_ID]=$T29,ChangeLog[Change'#],"")),"")} | T29: 19
A30: ASIAN GAMES | B30: 1954 | C30: ATHLETICS | D30: ATHLETICS | E30: TRACK | F30: WOMEN | G30: 100M | H30: ATHLETICS | I30: 100M (12.5) | J30: MARY KLASS | K30: SGP | M30: SILVER | N30: 2 | O30: 1 | P30: NO | Q30: YES | R30: 12.5 | S30: {=IFERROR(_xlfn.TEXTJOIN(", ",TRUE,IF(ChangeLog[ROW_ID]=$T30,ChangeLog[Change'#],"")),"")} | T30: 20
A31: ASIAN GAMES | B31: 1954 | C31: BOXING | D31: BOXING | E31: BOXING | G31: WELTERWEIGHT | H31: BOXING | I31: WELTERWEIGHT (UP TO 67KG) | J31: BULAT BIN ISMAIL | K31: SGP | M31: SILVER | N31: 2 | O31: 1 | P31: NO | Q31: YES | R31: up to 67kg | S31: {=IFERROR(_xlfn.TEXTJOIN(", ",TRUE,IF(ChangeLog[ROW_ID]=$T31,ChangeLog[Change'#],"")),"")} | T31: 21
A32: ASIAN GAMES | B32: 1954 | C32: WEIGHTLIFTING | D32: WEIGHTLIFTING | E32: WEIGHTLIFTING | G32: FEATHERWEIGHT | H32: WEIGHTLIFTING | I32: FEATHERWEIGHT (60KG) | J32: CHAY WONG YEW | K32: SGP | M32: BRONZE | N32: 3 | O32: 1 | P32: NO | Q32: YES | R32: 60kg | S32: {=IFERROR(_xlfn.TEXTJOIN(", ",TRUE,IF(ChangeLog[ROW_ID]=$T32,ChangeLog[Change'#],"")),"")} | T32: 22
A33: ASIAN GAMES | B33: 1954 | C33: WEIGHTLIFTING | D33: WEIGHTLIFTING | E33: WEIGHTLIFTING | G33: LIGHT-HEAVYWEIGHT | H33: WEIGHTLIFTING | I33: LIGHT HEAVYWEIGHT (82.5KG) | J33: HAROLD DE CASTRO | K33: SGP | M33: BRONZE | N33: 3 | O33: 1 | P33: NO | Q33: YES | R33: 82.5kg | S33: {=IFERROR(_xlfn.TEXTJOIN(", ",TRUE,IF(ChangeLog[ROW_ID]=$T33,ChangeLog[Change'#],"")),"")} | T33: 23
A34: ASIAN GAMES | B34: 1958 | C34: AQUATICS | D34: WATER POLO | E34: WATER POLO | F34: MEN | G34: TEAM | H34: WATERPOLO | I34: TEAM | J34: ANDREW LIM DEREK GEORGE MITCHELL GAN ENG TECK ERIC YEO GAN ENG GUAN THIO GIM-HOCK JOHN BARRY MITCHELL TAN ENG BOCK TAN ENG LIANG | K34: SGP | M34: SILVER | N34: 2 | O34: 1 | P34: NO | Q34: YES | S34: {=IFERROR(_xlfn.TEXTJOIN(", ",TRUE,IF(ChangeLog[ROW_ID]=$T34,ChangeLog[Change'#],"")),"")} | T34: 24
A35: ASIAN GAMES | B35: 1958 | C35: BOXING | D35: BOXING | E35: BOXING | G35: BANTAMWEIGHT | H35: BOXING | I35: BANTAMWEIGHT | J35: JACINTO DIAZ | K35: SGP | M35: BRONZE | N35: 3 | O35: 1 | P35: NO | Q35: YES | S35: {=IFERROR(_xlfn.TEXTJOIN(", ",TRUE,IF(ChangeLog[ROW_ID]=$T35,ChangeLog[Change'#],"")),"")} | T35: 25
A36: ASIAN GAMES | B36: 1958 | C36: BOXING | D36: BOXING | E36: BOXING | G36: FEATHERWEIGHT | H36: BOXING | I36: FEATHERWEIGHT | J36: AUSTIN DERRICK DUNSFORD | K36: SGP | M36: BRONZE | N36: 3 | O36: 1 | P36: NO | Q36: YES | S36: {=IFERROR(_xlfn.TEXTJOIN(", ",TRUE,IF(ChangeLog[ROW_ID]=$T36,ChangeLog[Change'#],"")),"")} | T36: 26
A37: ASIAN GAMES | B37: 1958 | C37: WEIGHTLIFTING | D37: WEIGHTLIFTING | E37: WEIGHTLIFTING | F37: MEN | G37: LIGHTWEIGHT | H37: WEIGHTLIFTING | I37: LIGHTWEIGHT (67.5KG) | J37: TAN HOWE LIANG | K37: SGP | M37: GOLD | N37: 1 | O37: 1 | P37: NO | Q37: YES | R37: 67.5kg | S37: {=IFERROR(_xlfn.TEXTJOIN(", ",TRUE,IF(ChangeLog[ROW_ID]=$T37,ChangeLog[Change'#],"")),"")} | T37: 27
A38: ASIAN GAMES | B38: 1962 | C38: AQUATICS | D38: WATER POLO | E38: WATER POLO | G38: TEAM | H38: WATERPOLO | I38: TEAM | J38: SINGAPORE | K38: SGP | M38: BRONZE | N38: 3 | O38: 1 | P38: NO | Q38: YES | S38: {=IFERROR(_xlfn.TEXTJOIN(", ",TRUE,IF(ChangeLog[ROW_ID]=$T38,ChangeLog[Change'#],"")),"")} | T38: 28
A39: ASIAN GAMES | B39: 1962 | C39: SHOOTING | D39: SHOOTING | E39: RIFLE | F39: MEN | G39: 50M RIFLE PRONE | H39: SHOOTING | I39: SMALL BORE RIFLE PRONE 50M (583 POINTS) | J39: FRED B DE SOUZA | K39: SGP | M39: GOLD | N39: 1 | O39: 1 | P39: NO | Q39: YES | R39: 583 points | S39: {=IFERROR(_xlfn.TEXTJOIN(", ",TRUE,IF(ChangeLog[ROW_ID]=$T39,ChangeLog[Change'#],"")),"")} | T39: 29
A40: ASIAN GAMES | B40: 1962 | C40: TABLE TENNIS | D40: TABLE TENNIS | E40: TABLE TENNIS | F40: MEN | G40: TEAM | H40: TABLE TENNIS | I40: MEN'S TEAM | J40: LIM WAI SHENG LIM JIN CHOON GOH SOO NAM SIM POH LIN | K40: SGP | M40: BRONZE | N40: 3 | O40: 1 | P40: NO | Q40: YES | S40: {=IFERROR(_xlfn.TEXTJOIN(", ",TRUE,IF(ChangeLog[ROW_ID]=$T40,ChangeLog[Change'#],"")),"")} | T40: 30
...

Sheet Change Log
A1: Change Log — Original vs Cleaned (for admin review)
A2: Cleaned sheet is based off Richard Gordon's Medal Tally + HPSI's Major Games Results Date File (for Names)
A4: Change# | B4: Type | C4: Alert | D4: Games | E4: ORIGINAL Athlete | F4: Year | G4: Field(s) Changed | H4: Reason for Change | I4: ORIGINAL Sport | J4: ORIGINAL Event | K4: ORIGINAL Medal | L4: CLEANED Sport | M4: CLEANED Discipline | N4: CLEANED Event | O4: CLEANED Medal | P4: CLEANED Athlete | Q4: Orig Row | R4: Clean Row | S4: Status (Accept/Reject) | T4: ROW_ID
A5: 1 | B5: Modified | D5: SEA Games | E5: {=IF(NOT(ISNUMBER(ChangeLog[[#This Row],[Orig Row]])),"",IFERROR(INDEX(IF(ChangeLog[[#This Row],[Games]]="SEA Games",'SNOC SEAG'!$A:$A,IF(ChangeLog[[#This Row],[Games]]="Olympic Games",'SNOC OG'!$A:$A,IF(ChangeLog[[#This Row],[Games]]="Commonweatlh Games",'SNOC CW Games'!$A:$A,'SNOC AG'!$A:$A))),ChangeLog[[#This Row],[Orig Row]]),""))} -> Ong Chew Bee | F5: 1959 | G5: Sport | H5: Lawn Tennis to Tennis as Sport | I5: {=IF(NOT(ISNUMBER(ChangeLog[[#This Row],[Orig Row]])),"",IFERROR(IF(INDEX(IF(ChangeLog[[#This Row],[Games]]="SEA Games",'SNOC SEAG'!$B:$B,IF(ChangeLog[[#This Row],[Games]]="Olympic Games",'SNOC OG'!$B:$B,IF(ChangeLog[[#This Row],[Games]]="Commonweatlh Games",'SNOC CW Games'!$B:$B,'SNOC AG'!$B:$B))),ChangeLog[[#This Row],[Orig Row]])="","",INDEX(IF(ChangeLog[[#This Row],[Games]]="SEA Games",'SNOC SEAG'!$B:$B,IF(ChangeLog[[#This Row],[Games]]="Olympic Games",'SNOC OG'!$B:$B,IF(ChangeLog[[#This Row],[Games]]="Commonweatlh Games",'SNOC CW Games'!$B:$B,'SNOC AG'!$B:$B))),ChangeLog[[#This Row],[Orig Row]])),""))} -> Lawn Tennis | J5: {=IF(NOT(ISNUMBER(ChangeLog[[#This Row],[Orig Row]])),"",IFERROR(IF(INDEX(IF(ChangeLog[[#This Row],[Games]]="SEA Games",'SNOC SEAG'!$C:$C,IF(ChangeLog[[#This Row],[Games]]="Olympic Games",'SNOC OG'!$C:$C,IF(ChangeLog[[#This Row],[Games]]="Commonweatlh Games",'SNOC CW Games'!$C:$C,'SNOC AG'!$C:$C))),ChangeLog[[#This Row],[Orig Row]])="","",INDEX(IF(ChangeLog[[#This Row],[Games]]="SEA Games",'SNOC SEAG'!$C:$C,IF(ChangeLog[[#This Row],[Games]]="Olympic Games",'SNOC OG'!$C:$C,IF(ChangeLog[[#This Row],[Games]]="Commonweatlh Games",'SNOC CW Games'!$C:$C,'SNOC AG'!$C:$C))),ChangeLog[[#This Row],[Orig Row]])),""))} -> Men's singles | K5: {=IF(NOT(ISNUMBER(ChangeLog[[#This Row],[Orig Row]])),"",IFERROR(IF(INDEX(IF(ChangeLog[[#This Row],[Games]]="SEA Games",'SNOC SEAG'!$D:$D,IF(ChangeLog[[#This Row],[Games]]="Olympic Games",'SNOC OG'!$D:$D,IF(ChangeLog[[#This Row],[Games]]="Commonweatlh Games",'SNOC CW Games'!$D:$D,'SNOC AG'!$D:$D))),ChangeLog[[#This Row],[Orig Row]])="","",INDEX(IF(ChangeLog[[#This Row],[Games]]="SEA Games",'SNOC SEAG'!$D:$D,IF(ChangeLog[[#This Row],[Games]]="Olympic Games",'SNOC OG'!$D:$D,IF(ChangeLog[[#This Row],[Games]]="Commonweatlh Games",'SNOC CW Games'!$D:$D,'SNOC AG'!$D:$D))),ChangeLog[[#This Row],[Orig Row]])),""))} -> Bronze | L5: =IFERROR(IF(INDEX('Consolidated Games'!$D:$D,MATCH(ChangeLog[[#This Row],[ROW_ID]],'Consolidated Games'!$T:$T,0))="","",INDEX('Consolidated Games'!$D:$D,MATCH(ChangeLog[[#This Row],[ROW_ID]],'Consolidated Games'!$T:$T,0))),"") -> TENNIS | M5: =IFERROR(IF(INDEX('Consolidated Games'!$E:$E,MATCH(ChangeLog[[#This Row],[ROW_ID]],'Consolidated Games'!$T:$T,0))="","",INDEX('Consolidated Games'!$E:$E,MATCH(ChangeLog[[#This Row],[ROW_ID]],'Consolidated Games'!$T:$T,0))),"") -> TENNIS | N5: {=IF(NOT(ISNUMBER(ChangeLog[[#This Row],[Clean Row]])),"",IFERROR(IF(INDEX('Consolidated Games'!$G:$G,ChangeLog[[#This Row],[Clean Row]])="","",INDEX('Consolidated Games'!$G:$G,ChangeLog[[#This Row],[Clean Row]])),""))} -> SINGLES | O5: =IFERROR(IF(INDEX('Consolidated Games'!$M:$M,MATCH(ChangeLog[[#This Row],[ROW_ID]],'Consolidated Games'!$T:$T,0))="","",INDEX('Consolidated Games'!$M:$M,MATCH(ChangeLog[[#This Row],[ROW_ID]],'Consolidated Games'!$T:$T,0))),"") -> BRONZE | P5: {=IF(NOT(ISNUMBER(ChangeLog[[#This Row],[Clean Row]])),"",IFERROR(IF(INDEX('Consolidated Games'!$J:$J,ChangeLog[[#This Row],[Clean Row]])="","",INDEX('Consolidated Games'!$J:$J,ChangeLog[[#This Row],[Clean Row]])),""))} -> ONG CHEW BEE | Q5: 19 | R5: =IFERROR(MATCH(T5,'Consolidated Games'!$T:$T,0),"—") -> 733 | S5: Accept | T5: 718
A6: 2 | B6: Modified | D6: SEA Games | E6: {=IF(NOT(ISNUMBER(ChangeLog[[#This Row],[Orig Row]])),"",IFERROR(INDEX(IF(ChangeLog[[#This Row],[Games]]="SEA Games",'SNOC SEAG'!$A:$A,IF(ChangeLog[[#This Row],[Games]]="Olympic Games",'SNOC OG'!$A:$A,IF(ChangeLog[[#This Row],[Games]]="Commonweatlh Games",'SNOC CW Games'!$A:$A,'SNOC AG'!$A:$A))),ChangeLog[[#This Row],[Orig Row]]),""))} -> Ong Chew Bee_x000D_ Khong Kit Soon | F6: 1959 | G6: Sport | H6: Lawn Tennis to Tennis as Sport | I6: {=IF(NOT(ISNUMBER(ChangeLog[[#This Row],[Orig Row]])),"",IFERROR(IF(INDEX(IF(ChangeLog[[#This Row],[Games]]="SEA Games",'SNOC SEAG'!$B:$B,IF(ChangeLog[[#This Row],[Games]]="Olympic Games",'SNOC OG'!$B:$B,IF(ChangeLog[[#This Row],[Games]]="Commonweatlh Games",'SNOC CW Games'!$B:$B,'SNOC AG'!$B:$B))),ChangeLog[[#This Row],[Orig Row]])="","",INDEX(IF(ChangeLog[[#This Row],[Games]]="SEA Games",'SNOC SEAG'!$B:$B,IF(ChangeLog[[#This Row],[Games]]="Olympic Games",'SNOC OG'!$B:$B,IF(ChangeLog[[#This Row],[Games]]="Commonweatlh Games",'SNOC CW Games'!$B:$B,'SNOC AG'!$B:$B))),ChangeLog[[#This Row],[Orig Row]])),""))} -> Lawn Tennis | J6: {=IF(NOT(ISNUMBER(ChangeLog[[#This Row],[Orig Row]])),"",IFERROR(IF(INDEX(IF(ChangeLog[[#This Row],[Games]]="SEA Games",'SNOC SEAG'!$C:$C,IF(ChangeLog[[#This Row],[Games]]="Olympic Games",'SNOC OG'!$C:$C,IF(ChangeLog[[#This Row],[Games]]="Commonweatlh Games",'SNOC CW Games'!$C:$C,'SNOC AG'!$C:$C))),ChangeLog[[#This Row],[Orig Row]])="","",INDEX(IF(ChangeLog[[#This Row],[Games]]="SEA Games",'SNOC SEAG'!$C:$C,IF(ChangeLog[[#This Row],[Games]]="Olympic Games",'SNOC OG'!$C:$C,IF(ChangeLog[[#This Row],[Games]]="Commonweatlh Games",'SNOC CW Games'!$C:$C,'SNOC AG'!$C:$C))),ChangeLog[[#This Row],[Orig Row]])),""))} -> Men's doubles | K6: {=IF(NOT(ISNUMBER(ChangeLog[[#This Row],[Orig Row]])),"",IFERROR(IF(INDEX(IF(ChangeLog[[#This Row],[Games]]="SEA Games",'SNOC SEAG'!$D:$D,IF(ChangeLog[[#This Row],[Games]]="Olympic Games",'SNOC OG'!$D:$D,IF(ChangeLog[[#This Row],[Games]]="Commonweatlh Games",'SNOC CW Games'!$D:$D,'SNOC AG'!$D:$D))),ChangeLog[[#This Row],[Orig Row]])="","",INDEX(IF(ChangeLog[[#This Row],[Games]]="SEA Games",'SNOC SEAG'!$D:$D,IF(ChangeLog[[#This Row],[Games]]="Olympic Games",'SNOC OG'!$D:$D,IF(ChangeLog[[#This Row],[Games]]="Commonweatlh Games",'SNOC CW Games'!$D:$D,'SNOC AG'!$D:$D))),ChangeLog[[#This Row],[Orig Row]])),""))} -> Bronze | L6: =IFERROR(IF(INDEX('Consolidated Games'!$D:$D,MATCH(ChangeLog[[#This Row],[ROW_ID]],'Consolidated Games'!$T:$T,0))="","",INDEX('Consolidated Games'!$D:$D,MATCH(ChangeLog[[#This Row],[ROW_ID]],'Consolidated Games'!$T:$T,0))),"") -> TENNIS | M6: =IFERROR(IF(INDEX('Consolidated Games'!$E:$E,MATCH(ChangeLog[[#This Row],[ROW_ID]],'Consolidated Games'!$T:$T,0))="","",INDEX('Consolidated Games'!$E:$E,MATCH(ChangeLog[[#This Row],[ROW_ID]],'Consolidated Games'!$T:$T,0))),"") -> TENNIS | N6: {=IF(NOT(ISNUMBER(ChangeLog[[#This Row],[Clean Row]])),"",IFERROR(IF(INDEX('Consolidated Games'!$G:$G,ChangeLog[[#This Row],[Clean Row]])="","",INDEX('Consolidated Games'!$G:$G,ChangeLog[[#This Row],[Clean Row]])),""))} -> DOUBLES | O6: =IFERROR(IF(INDEX('Consolidated Games'!$M:$M,MATCH(ChangeLog[[#This Row],[ROW_ID]],'Consolidated Games'!$T:$T,0))="","",INDEX('Consolidated Games'!$M:$M,MATCH(ChangeLog[[#This Row],[ROW_ID]],'Consolidated Games'!$T:$T,0))),"") -> BRONZE | P6: {=IF(NOT(ISNUMBER(ChangeLog[[#This Row],[Clean Row]])),"",IFERROR(IF(INDEX('Consolidated Games'!$J:$J,ChangeLog[[#This Row],[Clean Row]])="","",INDEX('Consolidated Games'!$J:$J,ChangeLog[[#This Row],[Clean Row]])),""))} -> ONG CHEW BEE_x000D_ KHONG KIT SOON | Q6: 20 | R6: =IFERROR(MATCH(T6,'Consolidated Games'!$T:$T,0),"—") -> 734 | S6: Accept | T6: 719
A7: 3 | B7: Modified | C7: Y | D7: SEA Games | E7: {=IF(NOT(ISNUMBER(ChangeLog[[#This Row],[Orig Row]])),"",IFERROR(INDEX(IF(ChangeLog[[#This Row],[Games]]="SEA Games",'SNOC SEAG'!$A:$A,IF(ChangeLog[[#This Row],[Games]]="Olympic Games",'SNOC OG'!$A:$A,IF(ChangeLog[[#This Row],[Games]]="Commonweatlh Games",'SNOC CW Games'!$A:$A,'SNOC AG'!$A:$A))),ChangeLog[[#This Row],[Orig Row]]),""))} -> Tan Gek Khee_x000D_ Siah Pong Pin_x000D_ Goh Soon Hock_x000D_ Fong Hoe Beng | F7: 1959 | G7: Medal | H7: NA Medal, changed to Bronze https://en.wikipedia.org/wiki/Swimming_at_the_1959_SEAP_Games; https://eresources.nlb.gov.sg/newspapers/digitised/article/straitstimes19591218-1.2.133 | I7: {=IF(NOT(ISNUMBER(ChangeLog[[#This Row],[Orig Row]])),"",IFERROR(IF(INDEX(IF(ChangeLog[[#This Row],[Games]]="SEA Games",'SNOC SEAG'!$B:$B,IF(ChangeLog[[#This Row],[Games]]="Olympic Games",'SNOC OG'!$B:$B,IF(ChangeLog[[#This Row],[Games]]="Commonweatlh Games",'SNOC CW Games'!$B:$B,'SNOC AG'!$B:$B))),ChangeLog[[#This Row],[Orig Row]])="","",INDEX(IF(ChangeLog[[#This Row],[Games]]="SEA Games",'SNOC SEAG'!$B:$B,IF(ChangeLog[[#This Row],[Games]]="Olympic Games",'SNOC OG'!$B:$B,IF(ChangeLog[[#This Row],[Games]]="Commonweatlh Games",'SNOC CW Games'!$B:$B,'SNOC AG'!$B:$B))),ChangeLog[[#This Row],[Orig Row]])),""))} -> Swimming | J7: {=IF(NOT(ISNUMBER(ChangeLog[[#This Row],[Orig Row]])),"",IFERROR(IF(INDEX(IF(ChangeLog[[#This Row],[Games]]="SEA Games",'SNOC SEAG'!$C:$C,IF(ChangeLog[[#This Row],[Games]]="Olympic Games",'SNOC OG'!$C:$C,IF(ChangeLog[[#This Row],[Games]]="Commonweatlh Games",'SNOC CW Games'!$C:$C,'SNOC AG'!$C:$C))),ChangeLog[[#This Row],[Orig Row]])="","",INDEX(IF(ChangeLog[[#This Row],[Games]]="SEA Games",'SNOC SEAG'!$C:$C,IF(ChangeLog[[#This Row],[Games]]="Olympic Games",'SNOC OG'!$C:$C,IF(ChangeLog[[#This Row],[Games]]="Commonweatlh Games",'SNOC CW Games'!$C:$C,'SNOC AG'!$C:$C))),ChangeLog[[#This Row],[Orig Row]])),""))} -> 400m medley relay | K7: {=IF(NOT(ISNUMBER(ChangeLog[[#This Row],[Orig Row]])),"",IFERROR(IF(INDEX(IF(ChangeLog[[#This Row],[Games]]="SEA Games",'SNOC SEAG'!$D:$D,IF(ChangeLog[[#This Row],[Games]]="Olympic Games",'SNOC OG'!$D:$D,IF(ChangeLog[[#This Row],[Games]]="Commonweatlh Games",'SNOC CW Games'!$D:$D,'SNOC AG'!$D:$D))),ChangeLog[[#This Row],[Orig Row]])="","",INDEX(IF(ChangeLog[[#This Row],[Games]]="SEA Games",'SNOC SEAG'!$D:$D,IF(ChangeLog[[#This Row],[Games]]="Olympic Games",'SNOC OG'!$D:$D,IF(ChangeLog[[#This Row],[Games]]="Commonweatlh Games",'SNOC CW Games'!$D:$D,'SNOC AG'!$D:$D))),ChangeLog[[#This Row],[Orig Row]])),""))} | L7: =IFERROR(IF(INDEX('Consolidated Games'!$D:$D,MATCH(ChangeLog[[#This Row],[ROW_ID]],'Consolidated Games'!$T:$T,0))="","",INDEX('Consolidated Games'!$D:$D,MATCH(ChangeLog[[#This Row],[ROW_ID]],'Consolidated Games'!$T:$T,0))),"") | M7: =IFERROR(IF(INDEX('Consolidated Games'!$E:$E,MATCH(ChangeLog[[#This Row],[ROW_ID]],'Consolidated Games'!$T:$T,0))="","",INDEX('Consolidated Games'!$E:$E,MATCH(ChangeLog[[#This Row],[ROW_ID]],'Consolidated Games'!$T:$T,0))),"") | N7: {=IF(NOT(ISNUMBER(ChangeLog[[#This Row],[Clean Row]])),"",IFERROR(IF(INDEX('Consolidated Games'!$G:$G,ChangeLog[[#This Row],[Clean Row]])="","",INDEX('Consolidated Games'!$G:$G,ChangeLog[[#This Row],[Clean Row]])),""))} | O7: =IFERROR(IF(INDEX('Consolidated Games'!$M:$M,MATCH(ChangeLog[[#This Row],[ROW_ID]],'Consolidated Games'!$T:$T,0))="","",INDEX('Consolidated Games'!$M:$M,MATCH(ChangeLog[[#This Row],[ROW_ID]],'Consolidated Games'!$T:$T,0))),"") | P7: {=IF(NOT(ISNUMBER(ChangeLog[[#This Row],[Clean Row]])),"",IFERROR(IF(INDEX('Consolidated Games'!$J:$J,ChangeLog[[#This Row],[Clean Row]])="","",INDEX('Consolidated Games'!$J:$J,ChangeLog[[#This Row],[Clean Row]])),""))} | Q7: 29 | R7: =IFERROR(MATCH(T7,'Consolidated Games'!$T:$T,0),"—") -> — | S7: Reject; inclined to follow SNOC & Wiki as microfiche doesn’t look accurate
A8: 4 | B8: Modified | C8: Y | D8: SEA Games | E8: {=IF(NOT(ISNUMBER(ChangeLog[[#This Row],[Orig Row]])),"",IFERROR(INDEX(IF(ChangeLog[[#This Row],[Games]]="SEA Games",'SNOC SEAG'!$A:$A,IF(ChangeLog[[#This Row],[Games]]="Olympic Games",'SNOC OG'!$A:$A,IF(ChangeLog[[#This Row],[Games]]="Commonweatlh Games",'SNOC CW Games'!$A:$A,'SNOC AG'!$A:$A))),ChangeLog[[#This Row],[Orig Row]]),""))} -> Boo Gim Siong | F8: 1961 | G8: Sport, Event | H8: Boo Gim Siong won in weightlifting, not swimming | I8: {=IF(NOT(ISNUMBER(ChangeLog[[#This Row],[Orig Row]])),"",IFERROR(IF(INDEX(IF(ChangeLog[[#This Row],[Games]]="SEA Games",'SNOC SEAG'!$B:$B,IF(ChangeLog[[#This Row],[Games]]="Olympic Games",'SNOC OG'!$B:$B,IF(ChangeLog[[#This Row],[Games]]="Commonweatlh Games",'SNOC CW Games'!$B:$B,'SNOC AG'!$B:$B))),ChangeLog[[#This Row],[Orig Row]])="","",INDEX(IF(ChangeLog[[#This Row],[Games]]="SEA Games",'SNOC SEAG'!$B:$B,IF(ChangeLog[[#This Row],[Games]]="Olympic Games",'SNOC OG'!$B:$B,IF(ChangeLog[[#This Row],[Games]]="Commonweatlh Games",'SNOC CW Games'!$B:$B,'SNOC AG'!$B:$B))),ChangeLog[[#This Row],[Orig Row]])),""))} -> Swimming | J8: {=IF(NOT(ISNUMBER(ChangeLog[[#This Row],[Orig Row]])),"",IFERROR(IF(INDEX(IF(ChangeLog[[#This Row],[Games]]="SEA Games",'SNOC SEAG'!$C:$C,IF(ChangeLog[[#This Row],[Games]]="Olympic Games",'SNOC OG'!$C:$C,IF(ChangeLog[[#This Row],[Games]]="Commonweatlh Games",'SNOC CW Games'!$C:$C,'SNOC AG'!$C:$C))),ChangeLog[[#This Row],[Orig Row]])="","",INDEX(IF(ChangeLog[[#This Row],[Games]]="SEA Games",'SNOC SEAG'!$C:$C,IF(ChangeLog[[#This Row],[Games]]="Olympic Games",'SNOC OG'!$C:$C,IF(ChangeLog[[#This Row],[Games]]="Commonweatlh Games",'SNOC CW Games'!$C:$C,'SNOC AG'!$C:$C))),ChangeLog[[#This Row],[Orig Row]])),""))} | K8: {=IF(NOT(ISNUMBER(ChangeLog[[#This Row],[Orig Row]])),"",IFERROR(IF(INDEX(IF(ChangeLog[[#This Row],[Games]]="SEA Games",'SNOC SEAG'!$D:$D,IF(ChangeLog[[#This Row],[Games]]="Olympic Games",'SNOC OG'!$D:$D,IF(ChangeLog[[#This Row],[Games]]="Commonweatlh Games",'SNOC CW Games'!$D:$D,'SNOC AG'!$D:$D))),ChangeLog[[#This Row],[Orig Row]])="","",INDEX(IF(ChangeLog[[#This Row],[Games]]="SEA Games",'SNOC SEAG'!$D:$D,IF(ChangeLog[[#This Row],[Games]]="Olympic Games",'SNOC OG'!$D:$D,IF(ChangeLog[[#This Row],[Games]]="Commonweatlh Games",'SNOC CW Games'!$D:$D,'SNOC AG'!$D:$D))),ChangeLog[[#This Row],[Orig Row]])),""))} -> Bronze | L8: =IFERROR(IF(INDEX('Consolidated Games'!$D:$D,MATCH(ChangeLog[[#This Row],[ROW_ID]],'Consolidated Games'!$T:$T,0))="","",INDEX('Consolidated Games'!$D:$D,MATCH(ChangeLog[[#This Row],[ROW_ID]],'Consolidated Games'!$T:$T,0))),"") -> WEIGHTLIFTING | M8: =IFERROR(IF(INDEX('Consolidated Games'!$E:$E,MATCH(ChangeLog[[#This Row],[ROW_ID]],'Consolidated Games'!$T:$T,0))="","",INDEX('Consolidated Games'!$E:$E,MATCH(ChangeLog[[#This Row],[ROW_ID]],'Consolidated Games'!$T:$T,0))),"") -> WEIGHTLIFTING | N8: {=IF(NOT(ISNUMBER(ChangeLog[[#This Row],[Clean Row]])),"",IFERROR(IF(INDEX('Consolidated Games'!$G:$G,ChangeLog[[#This Row],[Clean Row]])="","",INDEX('Consolidated Games'!$G:$G,ChangeLog[[#This Row],[Clean Row]])),""))} -> LIGHTWEIGHT | O8: =IFERROR(IF(INDEX('Consolidated Games'!$M:$M,MATCH(ChangeLog[[#This Row],[ROW_ID]],'Consolidated Games'!$T:$T,0))="","",INDEX('Consolidated Games'!$M:$M,MATCH(ChangeLog[[#This Row],[ROW_ID]],'Consolidated Games'!$T:$T,0))),"") -> BRONZE | P8: {=IF(NOT(ISNUMBER(ChangeLog[[#This Row],[Clean Row]])),"",IFERROR(IF(INDEX('Consolidated Games'!$J:$J,ChangeLog[[#This Row],[Clean Row]])="","",INDEX('Consolidated Games'!$J:$J,ChangeLog[[#This Row],[Clean Row]])),""))} -> BOO GIM SIONG | Q8: 52 | R8: =IFERROR(MATCH(T8,'Consolidated Games'!$T:$T,0),"—") -> 766 | S8: Accept | T8: 751
A9: 5 | B9: Modified | C9: Y | D9: SEA Games | E9: {=IF(NOT(ISNUMBER(ChangeLog[[#This Row],[Orig Row]])),"",IFERROR(INDEX(IF(ChangeLog[[#This Row],[Games]]="SEA Games",'SNOC SEAG'!$A:$A,IF(ChangeLog[[#This Row],[Games]]="Olympic Games",'SNOC OG'!$A:$A,IF(ChangeLog[[#This Row],[Games]]="Commonweatlh Games",'SNOC CW Games'!$A:$A,'SNOC AG'!$A:$A))),ChangeLog[[#This Row],[Orig Row]]),""))} -> Yeo Gim Cheong | F9: 1961 | G9: Sport, Event | H9: Yeo Gim Cheong won in weightlifting, not swimming https://eresources.nlb.gov.sg/newspapers/digitised/article/straitstimes19611216-1.2.131 | I9: {=IF(NOT(ISNUMBER(ChangeLog[[#This Row],[Orig Row]])),"",IFERROR(IF(INDEX(IF(ChangeLog[[#This Row],[Games]]="SEA Games",'SNOC SEAG'!$B:$B,IF(ChangeLog[[#This Row],[Games]]="Olympic Games",'SNOC OG'!$B:$B,IF(ChangeLog[[#This Row],[Games]]="Commonweatlh Games",'SNOC CW Games'!$B:$B,'SNOC AG'!$B:$B))),ChangeLog[[#This Row],[Orig Row]])="","",INDEX(IF(ChangeLog[[#This Row],[Games]]="SEA Games",'SNOC SEAG'!$B:$B,IF(ChangeLog[[#This Row],[Games]]="Olympic Games",'SNOC OG'!$B:$B,IF(ChangeLog[[#This Row],[Games]]="Commonweatlh Games",'SNOC CW Games'!$B:$B,'SNOC AG'!$B:$B))),ChangeLog[[#This Row],[Orig Row]])),""))} -> Swimming | J9: {=IF(NOT(ISNUMBER(ChangeLog[[#This Row],[Orig Row]])),"",IFERROR(IF(INDEX(IF(ChangeLog[[#This Row],[Games]]="SEA Games",'SNOC SEAG'!$C:$C,IF(ChangeLog[[#This Row],[Games]]="Olympic Games",'SNOC OG'!$C:$C,IF(ChangeLog[[#This Row],[Games]]="Commonweatlh Games",'SNOC CW Games'!$C:$C,'SNOC AG'!$C:$C))),ChangeLog[[#This Row],[Orig Row]])="","",INDEX(IF(ChangeLog[[#This Row],[Games]]="SEA Games",'SNOC SEAG'!$C:$C,IF(ChangeLog[[#This Row],[Games]]="Olympic Games",'SNOC OG'!$C:$C,IF(ChangeLog[[#This Row],[Games]]="Commonweatlh Games",'SNOC CW Games'!$C:$C,'SNOC AG'!$C:$C))),ChangeLog[[#This Row],[Orig Row]])),""))} | K9: {=IF(NOT(ISNUMBER(ChangeLog[[#This Row],[Orig Row]])),"",IFERROR(IF(INDEX(IF(ChangeLog[[#This Row],[Games]]="SEA Games",'SNOC SEAG'!$D:$D,IF(ChangeLog[[#This Row],[Games]]="Olympic Games",'SNOC OG'!$D:$D,IF(ChangeLog[[#This Row],[Games]]="Commonweatlh Games",'SNOC CW Games'!$D:$D,'SNOC AG'!$D:$D))),ChangeLog[[#This Row],[Orig Row]])="","",INDEX(IF(ChangeLog[[#This Row],[Games]]="SEA Games",'SNOC SEAG'!$D:$D,IF(ChangeLog[[#This Row],[Games]]="Olympic Games",'SNOC OG'!$D:$D,IF(ChangeLog[[#This Row],[Games]]="Commonweatlh Games",'SNOC CW Games'!$D:$D,'SNOC AG'!$D:$D))),ChangeLog[[#This Row],[Orig Row]])),""))} -> Bronze | L9: =IFERROR(IF(INDEX('Consolidated Games'!$D:$D,MATCH(ChangeLog[[#This Row],[ROW_ID]],'Consolidated Games'!$T:$T,0))="","",INDEX('Consolidated Games'!$D:$D,MATCH(ChangeLog[[#This Row],[ROW_ID]],'Consolidated Games'!$T:$T,0))),"") -> WEIGHTLIFTING | M9: =IFERROR(IF(INDEX('Consolidated Games'!$E:$E,MATCH(ChangeLog[[#This Row],[ROW_ID]],'Consolidated Games'!$T:$T,0))="","",INDEX('Consolidated Games'!$E:$E,MATCH(ChangeLog[[#This Row],[ROW_ID]],'Consolidated Games'!$T:$T,0))),"") -> WEIGHTLIFTING | N9: {=IF(NOT(ISNUMBER(ChangeLog[[#This Row],[Clean Row]])),"",IFERROR(IF(INDEX('Consolidated Games'!$G:$G,ChangeLog[[#This Row],[Clean Row]])="","",INDEX('Consolidated Games'!$G:$G,ChangeLog[[#This Row],[Clean Row]])),""))} -> LIGHT-HEAVYWEIGHT | O9: =IFERROR(IF(INDEX('Consolidated Games'!$M:$M,MATCH(ChangeLog[[#This Row],[ROW_ID]],'Consolidated Games'!$T:$T,0))="","",INDEX('Consolidated Games'!$M:$M,MATCH(ChangeLog[[#This Row],[ROW_ID]],'Consolidated Games'!$T:$T,0))),"") -> BRONZE | P9: {=IF(NOT(ISNUMBER(ChangeLog[[#This Row],[Clean Row]])),"",IFERROR(IF(INDEX('Consolidated Games'!$J:$J,ChangeLog[[#This Row],[Clean Row]])="","",INDEX('Consolidated Games'!$J:$J,ChangeLog[[#This Row],[Clean Row]])),""))} -> YEO GIM CHEONG | Q9: 55 | R9: =IFERROR(MATCH(T9,'Consolidated Games'!$T:$T,0),"—") -> 767 | S9: Accept | T9: 752
A10: 6 | B10: Modified | D10: SEA Games | E10: {=IF(NOT(ISNUMBER(ChangeLog[[#This Row],[Orig Row]])),"",IFERROR(INDEX(IF(ChangeLog[[#This Row],[Games]]="SEA Games",'SNOC SEAG'!$A:$A,IF(ChangeLog[[#This Row],[Games]]="Olympic Games",'SNOC OG'!$A:$A,IF(ChangeLog[[#This Row],[Games]]="Commonweatlh Games",'SNOC CW Games'!$A:$A,'SNOC AG'!$A:$A))),ChangeLog[[#This Row],[Orig Row]]),""))} -> Sharin Osman & T S Kim | F10: 1965 | G10: Sport | H10: Lawn Tennis to Tennis as Sport | I10: {=IF(NOT(ISNUMBER(ChangeLog[[#This Row],[Orig Row]])),"",IFERROR(IF(INDEX(IF(ChangeLog[[#This Row],[Games]]="SEA Games",'SNOC SEAG'!$B:$B,IF(ChangeLog[[#This Row],[Games]]="Olympic Games",'SNOC OG'!$B:$B,IF(ChangeLog[[#This Row],[Games]]="Commonweatlh Games",'SNOC CW Games'!$B:$B,'SNOC AG'!$B:$B))),ChangeLog[[#This Row],[Orig Row]])="","",INDEX(IF(ChangeLog[[#This Row],[Games]]="SEA Games",'SNOC SEAG'!$B:$B,IF(ChangeLog[[#This Row],[Games]]="Olympic Games",'SNOC OG'!$B:$B,IF(ChangeLog[[#This Row],[Games]]="Commonweatlh Games",'SNOC CW Games'!$B:$B,'SNOC AG'!$B:$B))),ChangeLog[[#This Row],[Orig Row]])),""))} -> Lawn Tennis | J10: {=IF(NOT(ISNUMBER(ChangeLog[[#This Row],[Orig Row]])),"",IFERROR(IF(INDEX(IF(ChangeLog[[#This Row],[Games]]="SEA Games",'SNOC SEAG'!$C:$C,IF(ChangeLog[[#This Row],[Games]]="Olympic Games",'SNOC OG'!$C:$C,IF(ChangeLog[[#This Row],[Games]]="Commonweatlh Games",'SNOC CW Games'!$C:$C,'SNOC AG'!$C:$C))),ChangeLog[[#This Row],[Orig Row]])="","",INDEX(IF(ChangeLog[[#This Row],[Games]]="SEA Games",'SNOC SEAG'!$C:$C,IF(ChangeLog[[#This Row],[Games]]="Olympic Games",'SNOC OG'!$C:$C,IF(ChangeLog[[#This Row],[Games]]="Commonweatlh Games",'SNOC CW Games'!$C:$C,'SNOC AG'!$C:$C))),ChangeLog[[#This Row],[Orig Row]])),""))} -> Men's Double | K10: {=IF(NOT(ISNUMBER(ChangeLog[[#This Row],[Orig Row]])),"",IFERROR(IF(INDEX(IF(ChangeLog[[#This Row],[Games]]="SEA Games",'SNOC SEAG'!$D:$D,IF(ChangeLog[[#This Row],[Games]]="Olympic Games",'SNOC OG'!$D:$D,IF(ChangeLog[[#This Row],[Games]]="Commonweatlh Games",'SNOC CW Games'!$D:$D,'SNOC AG'!$D:$D))),ChangeLog[[#This Row],[Orig Row]])="","",INDEX(IF(ChangeLog[[#This Row],[Games]]="SEA Games",'SNOC SEAG'!$D:$D,IF(ChangeLog[[#This Row],[Games]]="Olympic Games",'SNOC OG'!$D:$D,IF(ChangeLog[[#This Row],[Games]]="Commonweatlh Games",'SNOC CW Games'!$D:$D,'SNOC AG'!$D:$D))),ChangeLog[[#This Row],[Orig Row]])),""))} -> Bronze | L10: =IFERROR(IF(INDEX('Consolidated Games'!$D:$D,MATCH(ChangeLog[[#This Row],[ROW_ID]],'Consolidated Games'!$T:$T,0))="","",INDEX('Consolidated Games'!$D:$D,MATCH(ChangeLog[[#This Row],[ROW_ID]],'Consolidated Games'!$T:$T,0))),"") -> TENNIS | M10: =IFERROR(IF(INDEX('Consolidated Games'!$E:$E,MATCH(ChangeLog[[#This Row],[ROW_ID]],'Consolidated Games'!$T:$T,0))="","",INDEX('Consolidated Games'!$E:$E,MATCH(ChangeLog[[#This Row],[ROW_ID]],'Consolidated Games'!$T:$T,0))),"") -> TENNIS | N10: {=IF(NOT(ISNUMBER(ChangeLog[[#This Row],[Clean Row]])),"",IFERROR(IF(INDEX('Consolidated Games'!$G:$G,ChangeLog[[#This Row],[Clean Row]])="","",INDEX('Consolidated Games'!$G:$G,ChangeLog[[#This Row],[Clean Row]])),""))} -> DOUBLES | O10: =IFERROR(IF(INDEX('Consolidated Games'!$M:$M,MATCH(ChangeLog[[#This Row],[ROW_ID]],'Consolidated Games'!$T:$T,0))="","",INDEX('Consolidated Games'!$M:$M,MATCH(ChangeLog[[#This Row],[ROW_ID]],'Consolidated Games'!$T:$T,0))),"") -> BRONZE | P10: {=IF(NOT(ISNUMBER(ChangeLog[[#This Row],[Clean Row]])),"",IFERROR(IF(INDEX('Consolidated Games'!$J:$J,ChangeLog[[#This Row],[Clean Row]])="","",INDEX('Consolidated Games'!$J:$J,ChangeLog[[#This Row],[Clean Row]])),""))} -> SHARIN OSMAN & T S KIM | Q10: 91 | R10: =IFERROR(MATCH(T10,'Consolidated Games'!$T:$T,0),"—") -> 836 | S10: Accept | T10: 825
A11: 7 | B11: Removed (orig only) | D11: SEA Games | E11: {=IF(NOT(ISNUMBER(ChangeLog[[#This Row],[Orig Row]])),"",IFERROR(INDEX(IF(ChangeLog[[#This Row],[Games]]="SEA Games",'SNOC SEAG'!$A:$A,IF(ChangeLog[[#This Row],[Games]]="Olympic Games",'SNOC OG'!$A:$A,IF(ChangeLog[[#This Row],[Games]]="Commonweatlh Games",'SNOC CW Games'!$A:$A,'SNOC AG'!$A:$A))),ChangeLog[[#This Row],[Orig Row]]),""))} -> Cheong Kwok Chen | F11: 1965 | G11: Sport | H11: No medal. Finished 4th (newspaper article) | I11: {=IF(NOT(ISNUMBER(ChangeLog[[#This Row],[Orig Row]])),"",IFERROR(IF(INDEX(IF(ChangeLog[[#This Row],[Games]]="SEA Games",'SNOC SEAG'!$B:$B,IF(ChangeLog[[#This Row],[Games]]="Olympic Games",'SNOC OG'!$B:$B,IF(ChangeLog[[#This Row],[Games]]="Commonweatlh Games",'SNOC CW Games'!$B:$B,'SNOC AG'!$B:$B))),ChangeLog[[#This Row],[Orig Row]])="","",INDEX(IF(ChangeLog[[#This Row],[Games]]="SEA Games",'SNOC SEAG'!$B:$B,IF(ChangeLog[[#This Row],[Games]]="Olympic Games",'SNOC OG'!$B:$B,IF(ChangeLog[[#This Row],[Games]]="Commonweatlh Games",'SNOC CW Games'!$B:$B,'SNOC AG'!$B:$B))),ChangeLog[[#This Row],[Orig Row]])),""))} -> Swimming | J11: {=IF(NOT(ISNUMBER(ChangeLog[[#This Row],[Orig Row]])),"",IFERROR(IF(INDEX(IF(ChangeLog[[#This Row],[Games]]="SEA Games",'SNOC SEAG'!$C:$C,IF(ChangeLog[[#This Row],[Games]]="Olympic Games",'SNOC OG'!$C:$C,IF(ChangeLog[[#This Row],[Games]]="Commonweatlh Games",'SNOC CW Games'!$C:$C,'SNOC AG'!$C:$C))),ChangeLog[[#This Row],[Orig Row]])="","",INDEX(IF(ChangeLog[[#This Row],[Games]]="SEA Games",'SNOC SEAG'!$C:$C,IF(ChangeLog[[#This Row],[Games]]="Olympic Games",'SNOC OG'!$C:$C,IF(ChangeLog[[#This Row],[Games]]="Commonweatlh Games",'SNOC CW Games'!$C:$C,'SNOC AG'!$C:$C))),ChangeLog[[#This Row],[Orig Row]])),""))} -> Springboard diving (required dives) | K11: {=IF(NOT(ISNUMBER(ChangeLog[[#This Row],[Orig Row]])),"",IFERROR(IF(INDEX(IF(ChangeLog[[#This Row],[Games]]="SEA Games",'SNOC SEAG'!$D:$D,IF(ChangeLog[[#This Row],[Games]]="Olympic Games",'SNOC OG'!$D:$D,IF(ChangeLog[[#This Row],[Games]]="Commonweatlh Games",'SNOC CW Games'!$D:$D,'SNOC AG'!$D:$D))),ChangeLog[[#This Row],[Orig Row]])="","",INDEX(IF(ChangeLog[[#This Row],[Games]]="SEA Games",'SNOC SEAG'!$D:$D,IF(ChangeLog[[#This Row],[Games]]="Olympic Games",'SNOC OG'!$D:$D,IF(ChangeLog[[#This Row],[Games]]="Commonweatlh Games",'SNOC CW Games'!$D:$D,'SNOC AG'!$D:$D))),ChangeLog[[#This Row],[Orig Row]])),""))} -> Gold | L11: =IFERROR(IF(INDEX('Consolidated Games'!$D:$D,MATCH(ChangeLog[[#This Row],[ROW_ID]],'Consolidated Games'!$T:$T,0))="","",INDEX('Consolidated Games'!$D:$D,MATCH(ChangeLog[[#This Row],[ROW_ID]],'Consolidated Games'!$T:$T,0))),"") | M11: =IFERROR(IF(INDEX('Consolidated Games'!$E:$E,MATCH(ChangeLog[[#This Row],[ROW_ID]],'Consolidated Games'!$T:$T,0))="","",INDEX('Consolidated Games'!$E:$E,MATCH(ChangeLog[[#This Row],[ROW_ID]],'Consolidated Games'!$T:$T,0))),"") | N11: {=IF(NOT(ISNUMBER(ChangeLog[[#This Row],[Clean Row]])),"",IFERROR(IF(INDEX('Consolidated Games'!$G:$G,ChangeLog[[#This Row],[Clean Row]])="","",INDEX('Consolidated Games'!$G:$G,ChangeLog[[#This Row],[Clean Row]])),""))} | O11: =IFERROR(IF(INDEX('Consolidated Games'!$M:$M,MATCH(ChangeLog[[#This Row],[ROW_ID]],'Consolidated Games'!$T:$T,0))="","",INDEX('Consolidated Games'!$M:$M,MATCH(ChangeLog[[#This Row],[ROW_ID]],'Consolidated Games'!$T:$T,0))),"") | P11: {=IF(NOT(ISNUMBER(ChangeLog[[#This Row],[Clean Row]])),"",IFERROR(IF(INDEX('Consolidated Games'!$J:$J,ChangeLog[[#This Row],[Clean Row]])="","",INDEX('Consolidated Games'!$J:$J,ChangeLog[[#This Row],[Clean Row]])),""))} | Q11: 106 | R11: =IFERROR(MATCH(T11,'Consolidated Games'!$T:$T,0),"—") -> — | S11: Accept
A12: 8 | B12: Modified | D12: SEA Games | E12: {=IF(NOT(ISNUMBER(ChangeLog[[#This Row],[Orig Row]])),"",IFERROR(INDEX(IF(ChangeLog[[#This Row],[Games]]="SEA Games",'SNOC SEAG'!$A:$A,IF(ChangeLog[[#This Row],[Games]]="Olympic Games",'SNOC OG'!$A:$A,IF(ChangeLog[[#This Row],[Games]]="Commonweatlh Games",'SNOC CW Games'!$A:$A,'SNOC AG'!$A:$A))),ChangeLog[[#This Row],[Orig Row]]),""))} -> Hui Peng Seng (Diving) | F12: 1965 | G12: Sport | H12: Changed from Swimming to Diving as Sport | I12: {=IF(NOT(ISNUMBER(ChangeLog[[#This Row],[Orig Row]])),"",IFERROR(IF(INDEX(IF(ChangeLog[[#This Row],[Games]]="SEA Games",'SNOC SEAG'!$B:$B,IF(ChangeLog[[#This Row],[Games]]="Olympic Games",'SNOC OG'!$B:$B,IF(ChangeLog[[#This Row],[Games]]="Commonweatlh Games",'SNOC CW Games'!$B:$B,'SNOC AG'!$B:$B))),ChangeLog[[#This Row],[Orig Row]])="","",INDEX(IF(ChangeLog[[#This Row],[Games]]="SEA Games",'SNOC SEAG'!$B:$B,IF(ChangeLog[[#This Row],[Games]]="Olympic Games",'SNOC OG'!$B:$B,IF(ChangeLog[[#This Row],[Games]]="Commonweatlh Games",'SNOC CW Games'!$B:$B,'SNOC AG'!$B:$B))),ChangeLog[[#This Row],[Orig Row]])),""))} -> Swimming | J12: {=IF(NOT(ISNUMBER(ChangeLog[[#This Row],[Orig Row]])),"",IFERROR(IF(INDEX(IF(ChangeLog[[#This Row],[Games]]="SEA Games",'SNOC SEAG'!$C:$C,IF(ChangeLog[[#This Row],[Games]]="Olympic Games",'SNOC OG'!$C:$C,IF(ChangeLog[[#This Row],[Games]]="Commonweatlh Games",'SNOC CW Games'!$C:$C,'SNOC AG'!$C:$C))),ChangeLog[[#This Row],[Orig Row]])="","",INDEX(IF(ChangeLog[[#This Row],[Games]]="SEA Games",'SNOC SEAG'!$C:$C,IF(ChangeLog[[#This Row],[Games]]="Olympic Games",'SNOC OG'!$C:$C,IF(ChangeLog[[#This Row],[Games]]="Commonweatlh Games",'SNOC CW Games'!$C:$C,'SNOC AG'!$C:$C))),ChangeLog[[#This Row],[Orig Row]])),""))} -> Springboard diving (required dives) | K12: {=IF(NOT(ISNUMBER(ChangeLog[[#This Row],[Orig Row]])),"",IFERROR(IF(INDEX(IF(ChangeLog[[#This Row],[Games]]="SEA Games",'SNOC SEAG'!$D:$D,IF(ChangeLog[[#This Row],[Games]]="Olympic Games",'SNOC OG'!$D:$D,IF(ChangeLog[[#This Row],[Games]]="Commonweatlh Games",'SNOC CW Games'!$D:$D,'SNOC AG'!$D:$D))),ChangeLog[[#This Row],[Orig Row]])="","",INDEX(IF(ChangeLog[[#This Row],[Games]]="SEA Games",'SNOC SEAG'!$D:$D,IF(ChangeLog[[#This Row],[Games]]="Olympic Games",'SNOC OG'!$D:$D,IF(ChangeLog[[#This Row],[Games]]="Commonweatlh Games",'SNOC CW Games'!$D:$D,'SNOC AG'!$D:$D))),ChangeLog[[#This Row],[Orig Row]])),""))} -> Gold | L12: =IFERROR(IF(INDEX('Consolidated Games'!$D:$D,MATCH(ChangeLog[[#This Row],[ROW_ID]],'Consolidated Games'!$T:$T,0))="","",INDEX('Consolidated Games'!$D:$D,MATCH(ChangeLog[[#This Row],[ROW_ID]],'Consolidated Games'!$T:$T,0))),"") -> DIVING | M12: =IFERROR(IF(INDEX('Consolidated Games'!$E:$E,MATCH(ChangeLog[[#This Row],[ROW_ID]],'Consolidated Games'!$T:$T,0))="","",INDEX('Consolidated Games'!$E:$E,MATCH(ChangeLog[[#This Row],[ROW_ID]],'Consolidated Games'!$T:$T,0))),"") -> DIVING | N12: {=IF(NOT(ISNUMBER(ChangeLog[[#This Row],[Clean Row]])),"",IFERROR(IF(INDEX('Consolidated Games'!$G:$G,ChangeLog[[#This Row],[Clean Row]])="","",INDEX('Consolidated Games'!$G:$G,ChangeLog[[#This Row],[Clean Row]])),""))} -> 3M SPRINGBOARD | O12: =IFERROR(IF(INDEX('Consolidated Games'!$M:$M,MATCH(ChangeLog[[#This Row],[ROW_ID]],'Consolidated Games'!$T:$T,0))="","",INDEX('Consolidated Games'!$M:$M,MATCH(ChangeLog[[#This Row],[ROW_ID]],'Consolidated Games'!$T:$T,0))),"") -> GOLD | P12: {=IF(NOT(ISNUMBER(ChangeLog[[#This Row],[Clean Row]])),"",IFERROR(IF(INDEX('Consolidated Games'!$J:$J,ChangeLog[[#This Row],[Clean Row]])="","",INDEX('Consolidated Games'!$J:$J,ChangeLog[[#This Row],[Clean Row]])),""))} -> HUI PENG SENG (DIVING) | Q12: 109 | R12: =IFERROR(MATCH(T12,'Consolidated Games'!$T:$T,0),"—") -> 770 | S12: Accept | T12: 755
A13: 9 | B13: Modified | D13: SEA Games | E13: {=IF(NOT(ISNUMBER(ChangeLog[[#This Row],[Orig Row]])),"",IFERROR(INDEX(IF(ChangeLog[[#This Row],[Games]]="SEA Games",'SNOC SEAG'!$A:$A,IF(ChangeLog[[#This Row],[Games]]="Olympic Games",'SNOC OG'!$A:$A,IF(ChangeLog[[#This Row],[Games]]="Commonweatlh Games",'SNOC CW Games'!$A:$A,'SNOC AG'!$A:$A))),ChangeLog[[#This Row],[Orig Row]]),""))} -> Nora Tay | F13: 1965 | G13: Sport | H13: Changed from Swimming to Diving as Sport | I13: {=IF(NOT(ISNUMBER(ChangeLog[[#This Row],[Orig Row]])),"",IFERROR(IF(INDEX(IF(ChangeLog[[#This Row],[Games]]="SEA Games",'SNOC SEAG'!$B:$B,IF(ChangeLog[[#This Row],[Games]]="Olympic Games",'SNOC OG'!$B:$B,IF(ChangeLog[[#This Row],[Games]]="Commonweatlh Games",'SNOC CW Games'!$B:$B,'SNOC AG'!$B:$B))),ChangeLog[[#This Row],[Orig Row]])="","",INDEX(IF(ChangeLog[[#This Row],[Games]]="SEA Games",'SNOC SEAG'!$B:$B,IF(ChangeLog[[#This Row],[Games]]="Olympic Games",'SNOC OG'!$B:$B,IF(ChangeLog[[#This Row],[Games]]="Commonweatlh Games",'SNOC CW Games'!$B:$B,'SNOC AG'!$B:$B))),ChangeLog[[#This Row],[Orig Row]])),""))} -> Swimming | J13: {=IF(NOT(ISNUMBER(ChangeLog[[#This Row],[Orig Row]])),"",IFERROR(IF(INDEX(IF(ChangeLog[[#This Row],[Games]]="SEA Games",'SNOC SEAG'!$C:$C,IF(ChangeLog[[#This Row],[Games]]="Olympic Games",'SNOC OG'!$C:$C,IF(ChangeLog[[#This Row],[Games]]="Commonweatlh Games",'SNOC CW Games'!$C:$C,'SNOC AG'!$C:$C))),ChangeLog[[#This Row],[Orig Row]])="","",INDEX(IF(ChangeLog[[#This Row],[Games]]="SEA Games",'SNOC SEAG'!$C:$C,IF(ChangeLog[[#This Row],[Games]]="Olympic Games",'SNOC OG'!$C:$C,IF(ChangeLog[[#This Row],[Games]]="Commonweatlh Games",'SNOC CW Games'!$C:$C,'SNOC AG'!$C:$C))),ChangeLog[[#This Row],[Orig Row]])),""))} -> Springboard diving (required dives) | K13: {=IF(NOT(ISNUMBER(ChangeLog[[#This Row],[Orig Row]])),"",IFERROR(IF(INDEX(IF(ChangeLog[[#This Row],[Games]]="SEA Games",'SNOC SEAG'!$D:$D,IF(ChangeLog[[#This Row],[Games]]="Olympic Games",'SNOC OG'!$D:$D,IF(ChangeLog[[#This Row],[Games]]="Commonweatlh Games",'SNOC CW Games'!$D:$D,'SNOC AG'!$D:$D))),ChangeLog[[#This Row],[Orig Row]])="","",INDEX(IF(ChangeLog[[#This Row],[Games]]="SEA Games",'SNOC SEAG'!$D:$D,IF(ChangeLog[[#This Row],[Games]]="Olympic Games",'SNOC OG'!$D:$D,IF(ChangeLog[[#This Row],[Games]]="Commonweatlh Games",'SNOC CW Games'!$D:$D,'SNOC AG'!$D:$D))),ChangeLog[[#This Row],[Orig Row]])),""))} -> Gold | L13: =IFERROR(IF(INDEX('Consolidated Games'!$D:$D,MATCH(ChangeLog[[#This Row],[ROW_ID]],'Consolidated Games'!$T:$T,0))="","",INDEX('Consolidated Games'!$D:$D,MATCH(ChangeLog[[#This Row],[ROW_ID]],'Consolidated Games'!$T:$T,0))),"") -> DIVING | M13: =IFERROR(IF(INDEX('Consolidated Games'!$E:$E,MATCH(ChangeLog[[#This Row],[ROW_ID]],'Consolidated Games'!$T:$T,0))="","",INDEX('Consolidated Games'!$E:$E,MATCH(ChangeLog[[#This Row],[ROW_ID]],'Consolidated Games'!$T:$T,0))),"") -> DIVING | N13: {=IF(NOT(ISNUMBER(ChangeLog[[#This Row],[Clean Row]])),"",IFERROR(IF(INDEX('Consolidated Games'!$G:$G,ChangeLog[[#This Row],[Clean Row]])="","",INDEX('Consolidated Games'!$G:$G,ChangeLog[[#This Row],[Clean Row]])),""))} -> 3M SPRINGBOARD | O13: =IFERROR(IF(INDEX('Consolidated Games'!$M:$M,MATCH(ChangeLog[[#This Row],[ROW_ID]],'Consolidated Games'!$T:$T,0))="","",INDEX('Consolidated Games'!$M:$M,MATCH(ChangeLog[[#This Row],[ROW_ID]],'Consolidated Games'!$T:$T,0))),"") -> SILVER | P13: {=IF(NOT(ISNUMBER(ChangeLog[[#This Row],[Clean Row]])),"",IFERROR(IF(INDEX('Consolidated Games'!$J:$J,ChangeLog[[#This Row],[Clean Row]])="","",INDEX('Consolidated Games'!$J:$J,ChangeLog[[#This Row],[Clean Row]])),""))} -> NORA TAY | Q13: 110 | R13: =IFERROR(MATCH(T13,'Consolidated Games'!$T:$T,0),"—") -> 771 | S13: Accept | T13: 756
A14: 10 | B14: Removed (orig only) | D14: SEA Games | E14: {=IF(NOT(ISNUMBER(ChangeLog[[#This Row],[Orig Row]])),"",IFERROR(INDEX(IF(ChangeLog[[#This Row],[Games]]="SEA Games",'SNOC SEAG'!$A:$A,IF(ChangeLog[[#This Row],[Games]]="Olympic Games",'SNOC OG'!$A:$A,IF(ChangeLog[[#This Row],[Games]]="Commonweatlh Games",'SNOC CW Games'!$A:$A,'SNOC AG'!$A:$A))),ChangeLog[[#This Row],[Orig Row]]),""))} -> Nora Tay | F14: 1965 | G14: Sport | H14: Voluntary Dive not included in medal count | I14: {=IF(NOT(ISNUMBER(ChangeLog[[#This Row],[Orig Row]])),"",IFERROR(IF(INDEX(IF(ChangeLog[[#This Row],[Games]]="SEA Games",'SNOC SEAG'!$B:$B,IF(ChangeLog[[#This Row],[Games]]="Olympic Games",'SNOC OG'!$B:$B,IF(ChangeLog[[#This Row],[Games]]="Commonweatlh Games",'SNOC CW Games'!$B:$B,'SNOC AG'!$B:$B))),ChangeLog[[#This Row],[Orig Row]])="","",INDEX(IF(ChangeLog[[#This Row],[Games]]="SEA Games",'SNOC SEAG'!$B:$B,IF(ChangeLog[[#This Row],[Games]]="Olympic Games",'SNOC OG'!$B:$B,IF(ChangeLog[[#This Row],[Games]]="Commonweatlh Games",'SNOC CW Games'!$B:$B,'SNOC AG'!$B:$B))),ChangeLog[[#This Row],[Orig Row]])),""))} -> Swimming | J14: {=IF(NOT(ISNUMBER(ChangeLog[[#This Row],[Orig Row]])),"",IFERROR(IF(INDEX(IF(ChangeLog[[#This Row],[Games]]="SEA Games",'SNOC SEAG'!$C:$C,IF(ChangeLog[[#This Row],[Games]]="Olympic Games",'SNOC OG'!$C:$C,IF(ChangeLog[[#This Row],[Games]]="Commonweatlh Games",'SNOC CW Games'!$C:$C,'SNOC AG'!$C:$C))),ChangeLog[[#This Row],[Orig Row]])="","",INDEX(IF(ChangeLog[[#This Row],[Games]]="SEA Games",'SNOC SEAG'!$C:$C,IF(ChangeLog[[#This Row],[Games]]="Olympic Games",'SNOC OG'!$C:$C,IF(ChangeLog[[#This Row],[Games]]="Commonweatlh Games",'SNOC CW Games'!$C:$C,'SNOC AG'!$C:$C))),ChangeLog[[#This Row],[Orig Row]])),""))} -> Springboard diving (voluntary dives) | K14: {=IF(NOT(ISNUMBER(ChangeLog[[#This Row],[Orig Row]])),"",IFERROR(IF(INDEX(IF(ChangeLog[[#This Row],[Games]]="SEA Games",'SNOC SEAG'!$D:$D,IF(ChangeLog[[#This Row],[Games]]="Olympic Games",'SNOC OG'!$D:$D,IF(ChangeLog[[#This Row],[Games]]="Commonweatlh Games",'SNOC CW Games'!$D:$D,'SNOC AG'!$D:$D))),ChangeLog[[#This Row],[Orig Row]])="","",INDEX(IF(ChangeLog[[#This Row],[Games]]="SEA Games",'SNOC SEAG'!$D:$D,IF(ChangeLog[[#This Row],[Games]]="Olympic Games",'SNOC OG'!$D:$D,IF(ChangeLog[[#This Row],[Games]]="Commonweatlh Games",'SNOC CW Games'!$D:$D,'SNOC AG'!$D:$D))),ChangeLog[[#This Row],[Orig Row]])),""))} -> Silver | L14: =IFERROR(IF(INDEX('Consolidated Games'!$D:$D,MATCH(ChangeLog[[#This Row],[ROW_ID]],'Consolidated Games'!$T:$T,0))="","",INDEX('Consolidated Games'!$D:$D,MATCH(ChangeLog[[#This Row],[ROW_ID]],'Consolidated Games'!$T:$T,0))),"") | M14: =IFERROR(IF(INDEX('Consolidated Games'!$E:$E,MATCH(ChangeLog[[#This Row],[ROW_ID]],'Consolidated Games'!$T:$T,0))="","",INDEX('Consolidated Games'!$E:$E,MATCH(ChangeLog[[#This Row],[ROW_ID]],'Consolidated Games'!$T:$T,0))),"") | N14: {=IF(NOT(ISNUMBER(ChangeLog[[#This Row],[Clean Row]])),"",IFERROR(IF(INDEX('Consolidated Games'!$G:$G,ChangeLog[[#This Row],[Clean Row]])="","",INDEX('Consolidated Games'!$G:$G,ChangeLog[[#This Row],[Clean Row]])),""))} | O14: =IFERROR(IF(INDEX('Consolidated Games'!$M:$M,MATCH(ChangeLog[[#This Row],[ROW_ID]],'Consolidated Games'!$T:$T,0))="","",INDEX('Consolidated Games'!$M:$M,MATCH(ChangeLog[[#This Row],[ROW_ID]],'Consolidated Games'!$T:$T,0))),"") | P14: {=IF(NOT(ISNUMBER(ChangeLog[[#This Row],[Clean Row]])),"",IFERROR(IF(INDEX('Consolidated Games'!$J:$J,ChangeLog[[#This Row],[Clean Row]])="","",INDEX('Consolidated Games'!$J:$J,ChangeLog[[#This Row],[Clean Row]])),""))} | Q14: 133 | R14: =IFERROR(MATCH(T14,'Consolidated Games'!$T:$T,0),"—") -> — | S14: Accept
A15: 11 | B15: Modified | D15: SEA Games | E15: {=IF(NOT(ISNUMBER(ChangeLog[[#This Row],[Orig Row]])),"",IFERROR(INDEX(IF(ChangeLog[[#This Row],[Games]]="SEA Games",'SNOC SEAG'!$A:$A,IF(ChangeLog[[#This Row],[Games]]="Olympic Games",'SNOC OG'!$A:$A,IF(ChangeLog[[#This Row],[Games]]="Commonweatlh Games",'SNOC CW Games'!$A:$A,'SNOC AG'!$A:$A))),ChangeLog[[#This Row],[Orig Row]]),""))} -> Tan Eng Bock_x000D_ Tan Eng Liang_x000D_ Eric Yeo Oon Tat_x000D_ Tan Yam Cheng_x000D_ Lim Teck Pan_x000D_ Gan Eng Joo_x000D_ Su Hong Zee_x000D_ Pang Tee Ann_x000D_ Pang Chin She_x000D_ David Lim | F15: 1965 | G15: Sport | H15: Changed to Water Polo as Sport to align with downstream names | I15: {=IF(NOT(ISNUMBER(ChangeLog[[#This Row],[Orig Row]])),"",IFERROR(IF(INDEX(IF(ChangeLog[[#This Row],[Games]]="SEA Games",'SNOC SEAG'!$B:$B,IF(ChangeLog[[#This Row],[Games]]="Olympic Games",'SNOC OG'!$B:$B,IF(ChangeLog[[#This Row],[Games]]="Commonweatlh Games",'SNOC CW Games'!$B:$B,'SNOC AG'!$B:$B))),ChangeLog[[#This Row],[Orig Row]])="","",INDEX(IF(ChangeLog[[#This Row],[Games]]="SEA Games",'SNOC SEAG'!$B:$B,IF(ChangeLog[[#This Row],[Games]]="Olympic Games",'SNOC OG'!$B:$B,IF(ChangeLog[[#This Row],[Games]]="Commonweatlh Games",'SNOC CW Games'!$B:$B,'SNOC AG'!$B:$B))),ChangeLog[[#This Row],[Orig Row]])),""))} -> Waterpolo | J15: {=IF(NOT(ISNUMBER(ChangeLog[[#This Row],[Orig Row]])),"",IFERROR(IF(INDEX(IF(ChangeLog[[#This Row],[Games]]="SEA Games",'SNOC SEAG'!$C:$C,IF(ChangeLog[[#This Row],[Games]]="Olympic Games",'SNOC OG'!$C:$C,IF(ChangeLog[[#This Row],[Games]]="Commonweatlh Games",'SNOC CW Games'!$C:$C,'SNOC AG'!$C:$C))),ChangeLog[[#This Row],[Orig Row]])="","",INDEX(IF(ChangeLog[[#This Row],[Games]]="SEA Games",'SNOC SEAG'!$C:$C,IF(ChangeLog[[#This Row],[Games]]="Olympic Games",'SNOC OG'!$C:$C,IF(ChangeLog[[#This Row],[Games]]="Commonweatlh Games",'SNOC CW Games'!$C:$C,'SNOC AG'!$C:$C))),ChangeLog[[#This Row],[Orig Row]])),""))} -> On goal average | K15: {=IF(NOT(ISNUMBER(ChangeLog[[#This Row],[Orig Row]])),"",IFERROR(IF(INDEX(IF(ChangeLog[[#This Row],[Games]]="SEA Games",'SNOC SEAG'!$D:$D,IF(ChangeLog[[#This Row],[Games]]="Olympic Games",'SNOC OG'!$D:$D,IF(ChangeLog[[#This Row],[Games]]="Commonweatlh Games",'SNOC CW Games'!$D:$D,'SNOC AG'!$D:$D))),ChangeLog[[#This Row],[Orig Row]])="","",INDEX(IF(ChangeLog[[#This Row],[Games]]="SEA Games",'SNOC SEAG'!$D:$D,IF(ChangeLog[[#This Row],[Games]]="Olympic Games",'SNOC OG'!$D:$D,IF(ChangeLog[[#This Row],[Games]]="Commonweatlh Games",'SNOC CW Games'!$D:$D,'SNOC AG'!$D:$D))),ChangeLog[[#This Row],[Orig Row]])),""))} -> Gold | L15: =IFERROR(IF(INDEX('Consolidated Games'!$D:$D,MATCH(ChangeLog[[#This Row],[ROW_ID]],'Consolidated Games'!$T:$T,0))="","",INDEX('Consolidated Games'!$D:$D,MATCH(ChangeLog[[#This Row],[ROW_ID]],'Consolidated Games'!$T:$T,0))),"") -> WATER POLO | M15: =IFERROR(IF(INDEX('Consolidated Games'!$E:$E,MATCH(ChangeLog[[#This Row],[ROW_ID]],'Consolidated Games'!$T:$T,0))="","",INDEX('Consolidated Games'!$E:$E,MATCH(ChangeLog[[#This Row],[ROW_ID]],'Consolidated Games'!$T:$T,0))),"") -> WATER POLO | N15: {=IF(NOT(ISNUMBER(ChangeLog[[#This Row],[Clean Row]])),"",IFERROR(IF(INDEX('Consolidated Games'!$G:$G,ChangeLog[[#This Row],[Clean Row]])="","",INDEX('Consolidated Games'!$G:$G,ChangeLog[[#This Row],[Clean Row]])),""))} -> TEAM | O15: =IFERROR(IF(INDEX('Consolidated Games'!$M:$M,MATCH(ChangeLog[[#This Row],[ROW_ID]],'Consolidated Games'!$T:$T,0))="","",INDEX('Consolidated Games'!$M:$M,MATCH(ChangeLog[[#This Row],[ROW_ID]],'Consolidated Games'!$T:$T,0))),"") -> GOLD | P15: {=IF(NOT(ISNUMBER(ChangeLog[[#This Row],[Clean Row]])),"",IFERROR(IF(INDEX('Consolidated Games'!$J:$J,ChangeLog[[#This Row],[Clean Row]])="","",INDEX('Consolidated Games'!$J:$J,ChangeLog[[#This Row],[Clean Row]])),""))} -> TAN ENG BOCK_x000D_ TAN ENG LIANG_x000D_ ERIC YEO OON TAT_x000D_ TAN YAM CHENG_x000D_ LIM TECK PAN_x000D_ GAN ENG JOO_x000D_ SU HONG ZEE_x000D_ PANG TEE ANN_x000D_ PANG CHIN SHE_x000D_ DAVID LIM | Q15: 138 | R15: =IFERROR(MATCH(T15,'Consolidated Games'!$T:$T,0),"—") -> 772 | S15: Accept | T15: 757
